Workbook

Sheet Summary
A1: Estimate Sheet Summary
A2: Labor, Materials & Equipments
A3: Equipment Costs | B3: =Equipment!C3 -> 45
A4: IVU | B4: =B3*C4 -> 5.175 | C4: 0.115
A5: Sum | B5: =SUM(B3:B4) -> 50.175
A6: Subcontractor | B6: ='Sub-Contractors'!B15+'Sub-Contractors'!C15+'Sub-Contractors'!B29+'Sub-Contractors'!C29+'Sub-Contractors'!B43+'Sub-Contractors'!C43 -> 0
A7: B2B | B7: =(B6*0.35)*0.04 -> 0
A8: Sum | B8: =SUM(B6:B7) -> 0
A9: Materials | B9: {='Material & Labor'!B3:C3} -> 4100.78 | C9: 0
A10: IVU | B10: =B9*C10 -> 471.5897 | C10: 0.115
A11: Sum | B11: =SUM(B9:B10) -> 4572.3697
A12: Labor Regular | B12: {='Material & Labor'!H3:I3} -> 2578.048 | C12: 0
A13: Labor OT | B13: {='Material & Labor'!N3:O3} -> 0 | C13: 0
A14: Sum | B14: =SUM(B12:B13) -> 2578.048
A15: General Conditions | B15: {='General Conditions'!C3:E3} -> 172.5 | C15: 0 | D15: 0
A16: Transportacion | B16: =Roundtrip!C3 -> 0
A17: Sum | B17: =SUM(B15:B16) -> 172.5
A18: Sub-Total | B18: =B5+B8+B11+B14+B17 -> 7373.0927
A20: Profit & OH
A21: Profit | B21: =B18*C21 -> 589.84742 | C21: 0.08
A22: Sum | B22: =B18+B21 -> 7962.9401
A23: Overhead | B23: =B22*C23 -> 637.03521 | C23: 0.08
A24: Sum | B24: =B22+B23 -> 8599.9753
A26: Insurances
A27: CFSE | B27: =$B$14*C27 -> 180.46336 | C27: 0.07
A28: Sum | B28: =B24+B27 -> 8780.4387
A29: Liability | B29: =B28*C29 -> 614.63071 | C29: 0.07
A30: Sum | B30: =B28+B29 -> 9395.0694
A31: Municipal Patent | B31: =B30*C31 -> 93.950694 | C31: 0.01
A32: Sum | B32: =B30+B31 -> 9489.0201
A34: Arbitrios | B34: =B32*C34 -> 0 | C34: 0 | G34: Leyenda
A35: Bid Bond | B35: =B32*C35 -> 0 | C35: 0 | H35: Celda de input
A36: Performance Bond | B36: =B32*C36 -> 0 | C36: 0 | H36: Celda con formula
A37: Sub-Total | B37: =B32+B34+B35+B36 -> 9489.0201
A39: Project Cost | G39: Material/Equipment | H39: Labor | I39: Total
A40: Sub-Total | B40: =B37 -> 9489.0201 | G40: 6404.71 | H40: =I40-G40 -> 3650.14 | I40: 10054.85
A41: Contingency | B41: =B40*C41 -> 427.0059 | C41: 0.045
A42: Sub-Total | B42: =B40+B41 -> 9916.026
A43: B2B | B43: =(B42*0.35)*0.04 -> 138.82436 | G43: Form-OHSMS-E-0001
A44: TOTAL | B44: =B42+B43 -> 10054.85 | G44: Rev. 01 - 08/18/2025

Sheet Material & Labor
A1: Materials & Labor Costs
A2: Materials per Tasks | E2: Regular Labor Cost | K2: Over Time Labor Cost
A3: Total Materials Costs | B3: =B16+C16+B29+C29+B42+C42+B55+C55+B68+C68 -> 4100.78 | E3: Total Regular Labor Cost | H3: =I16+I29 -> 2578.048 | K3: Total OT Labor Cost | N3: =O16+O29 -> 0
A4: Description | B4: Quoted Cost | C4: Assumed Cost | E4: Qty | F4: Personnel | G4: Hours | H4: Rate | I4: Sub-Total | K4: Qty | L4: Personnel | M4: Hours | N4: Rate | O4: Sub-Total
A5: 6 ft., 9 in. x 2.3 in. x 1.5 in. 14-Gauge Green C Powder Coated Galvanized Steel Post | B5: 989.01 | E5: 1 | F5: Project Manager | G5: 4 | H5: 69.32 | I5: =E5*G5*H5 -> 277.28 | L5: Project Manager | N5: =1.5*H5 -> 103.98 | O5: =K5*N5*M5 -> 0
A6: 5 in. x 5 in. 14-Gauge Green Galvanized Steel Base-Coated Welded Wire | B6: 593.01 | F6: Project Engineer | H6: 41.79 | I6: =E6*G6*H6 -> 0 | L6: Project Engineer | N6: =1.5*H6 -> 62.685 | O6: =K6*N6*M6 -> 0
A7: 7/32 in. x 6-1/4 in. Zinc-Plated Turnbuckle Hook/Eye | B7: 425.04 | E7: 1 | F7: Supervisor | G7: 32 | H7: 26.31 | I7: =E7*G7*H7 -> 841.92 | L7: Supervisor | N7: =1.5*H7 -> 39.465 | O7: =K7*N7*M7 -> 0
A8: 5/16 in. x 4 in. Galvanized Eyebolt/Nut | B8: 394.68 | F8: Soldador | H8: 29.75 | I8: =E8*G8*H8 -> 0 | L8: Soldador | N8: =1.5*H8 -> 44.625 | O8: =K8*N8*M8 -> 0 | R8: Rate
A9: 1/4 in. Zinc-Plated Clamp Set (4-Pack) | B9: 642.84 | F9: Fabricador | H9: 28.03 | I9: =E9*G9*H9 -> 0 | L9: Fabricador | N9: =1.5*H9 -> 42.045 | O9: =K9*N9*M9 -> 0 | Q9: Sup | R9: 18 | S9: 4 | T9: =R9*S9 -> 72
A10: 1/8 in. x 250 ft. Galvanized Vinyl Coated Steel Wire Rope | B10: 466.4 | E10: 2 | F10: Ayudante | G10: 32 | H10: 21.15 | I10: =E10*G10*H10 -> 1353.6 | L10: Ayudante | N10: =1.5*H10 -> 31.725 | O10: =K10*N10*M10 -> 0 | Q10: Sold | R10: 13.5 | S10: 0 | T10: =R10*S10 -> 0
A11: 3/8 in. x 3 in. Zinc-Plated Steel Hex-Nut-Head Indoor Sleeve Anchors (15-Pack) | B11: 169.8 | F11: Instalador | H11: 22.87 | I11: =E11*G11*H11 -> 0 | L11: Instalador | N11: =1.5*H11 -> 34.305 | O11: =K11*N11*M11 -> 0 | Q11: Ayud | R11: 11 | S11: 4 | T11: =R11*S11 -> 44
A12: 6’ Height Privacy Screen | B12: 420 | F12: Ayudante | H12: 21.15 | I12: =E12*G12*H12 -> 0 | L12: Ayudante | N12: =1.5*H12 -> 31.725 | O12: =K12*N12*M12 -> 0 | Q12: Safety | R12: 17 | S12: 2 | T12: =R12*S12 -> 34
E13: 1 | F13: Safety | G13: 4 | H13: 26.312 | I13: =E13*G13*H13 -> 105.248 | L13: Safety | N13: =1.5*H13 -> 39.468 | O13: =K13*N13*M13 -> 0 | Q13: PM | R13: 38 | T13: =R13*S13 -> 0
F14: Carpintero | H14: 22.87 | I14: =E14*G14*H14 -> 0 | L14: Carpintero | N14: =1.5*H14 -> 34.305 | O14: =K14*N14*M14 -> 0 | T14: =SUM(T9:T13) -> 150
I15: =E15*G15*H15 -> 0 | O15: =K15*N15*M15 -> 0
A16: Sub-Total | B16: =SUM(B5:B15) -> 4100.78 | C16: =SUM(C5:C15) -> 0 | E16: Total | I16: =SUM(I5:I15) -> 2578.048 | K16: Total | O16: =SUM(O5:O15) -> 0
A17: Description | B17: Quoted Cost | C17: Assumed Cost | E17: Qty | F17: Personnel | G17: Hours | H17: Rate | I17: Sub-Total | K17: Qty | L17: Personnel | M17: Hours | N17: Rate | O17: Sub-Total | S17: Diferencia | T17: =H3-T14 -> 2428.048
F18: Project Manager | H18: 69.32 | I18: =E18*G18*H18 -> 0 | L18: Project Manager | N18: =1.5*H18 -> 103.98 | O18: =K18*N18*M18 -> 0
F19: Project Engineer | H19: 41.79 | I19: =E19*G19*H19 -> 0 | L19: Project Engineer | N19: =1.5*H19 -> 62.685 | O19: =K19*N19*M19 -> 0
F20: Supervisor | H20: 26.31 | I20: =E20*G20*H20 -> 0 | L20: Supervisor | N20: =1.5*H20 -> 39.465 | O20: =K20*N20*M20 -> 0 | Q20: Sup | R20: 18 | S20: 8 | T20: =R20*S20 -> 144
F21: Soldador | H21: 29.75 | I21: =E21*G21*H21 -> 0 | L21: Soldador | N21: =1.5*H21 -> 44.625 | O21: =K21*N21*M21 -> 0 | Q21: Sold | R21: 13.5 | S21: 8 | T21: =R21*S21 -> 108
F22: Fabricador | H22: 28.03 | I22: =E22*G22*H22 -> 0 | L22: Fabricador | N22: =1.5*H22 -> 42.045 | O22: =K22*N22*M22 -> 0 | Q22: Ayud | R22: 11 | S22: 8 | T22: =R22*S22 -> 88
F23: Ayudante | H23: 21.15 | I23: =E23*G23*H23 -> 0 | L23: Ayudante | N23: =1.5*H23 -> 31.725 | O23: =K23*N23*M23 -> 0 | Q23: Safety | R23: 17 | S23: 4 | T23: =R23*S23 -> 68
F24: Instalador | H24: 22.87 | I24: =E24*G24*H24 -> 0 | L24: Instalador | N24: =1.5*H24 -> 34.305 | O24: =K24*N24*M24 -> 0 | Q24: PM | R24: 38 | S24: 2 | T24: =R24*S24 -> 76
F25: Ayudante | H25: 21.15 | I25: =E25*G25*H25 -> 0 | L25: Ayudante | N25: =1.5*H25 -> 31.725 | O25: =K25*N25*M25 -> 0 | T25: =SUM(T20:T24) -> 484
F26: Safety | H26: 26.312 | I26: =E26*G26*H26 -> 0 | L26: Safety | N26: =1.5*H26 -> 39.468 | O26: =K26*N26*M26 -> 0
F27: Carpintero | H27: 22.87 | I27: =E27*G27*H27 -> 0 | L27: Carpintero | N27: =1.5*H27 -> 34.305 | O27: =K27*N27*M27 -> 0
I28: =E28*G28*H28 -> 0 | O28: =K28*N28*M28 -> 0
A29: Sub-Total | B29: =SUM(B18:B28) -> 0 | C29: =SUM(C18:C28) -> 0 | E29: Total | I29: =SUM(I18:I28) -> 0 | K29: Total | O29: =SUM(O18:O28) -> 0 | Q29: Dias @ Costos Reales | T29: =H3/T25 -> 5.3265455
A30: Description | B30: Quoted Cost | C30: Assumed Cost | E30: Qty | F30: Personnel | G30: Hours | H30: Rate | I30: Sub-Total | K30: Qty | L30: Personnel | M30: Hours | N30: Rate | O30: Sub-Total
F31: Project Manager | H31: 69.32 | I31: =E31*G31*H31 -> 0 | L31: Project Manager | N31: =1.5*H31 -> 103.98 | O31: =K31*N31*M31 -> 0
F32: Project Engineer | H32: 41.79 | I32: =E32*G32*H32 -> 0 | L32: Project Engineer | N32: =1.5*H32 -> 62.685 | O32: =K32*N32*M32 -> 0
F33: Supervisor | H33: 26.31 | I33: =E33*G33*H33 -> 0 | L33: Supervisor | N33: =1.5*H33 -> 39.465 | O33: =K33*N33*M33 -> 0
F34: Soldador | H34: 29.75 | I34: =E34*G34*H34 -> 0 | L34: Soldador | N34: =1.5*H34 -> 44.625 | O34: =K34*N34*M34 -> 0
F35: Fabricador | H35: 28.03 | I35: =E35*G35*H35 -> 0 | L35: Fabricador | N35: =1.5*H35 -> 42.045 | O35: =K35*N35*M35 -> 0
F36: Ayudante | H36: 21.15 | I36: =E36*G36*H36 -> 0 | L36: Ayudante | N36: =1.5*H36 -> 31.725 | O36: =K36*N36*M36 -> 0
F37: Instalador | H37: 22.87 | I37: =E37*G37*H37 -> 0 | L37: Instalador | N37: =1.5*H37 -> 34.305 | O37: =K37*N37*M37 -> 0
F38: Ayudante | H38: 21.15 | I38: =E38*G38*H38 -> 0 | L38: Ayudante | N38: =1.5*H38 -> 31.725 | O38: =K38*N38*M38 -> 0
F39: Safety | H39: 26.312 | I39: =E39*G39*H39 -> 0 | L39: Safety | N39: =1.5*H39 -> 39.468 | O39: =K39*N39*M39 -> 0
F40: Carpintero | H40: 22.87 | I40: =E40*G40*H40 -> 0 | L40: Carpintero | N40: =1.5*H40 -> 34.305 | O40: =K40*N40*M40 -> 0
...

Sheet Equipment
A1: Equipments Costs
A2: Equipment Rental
A3: Total Equipments Costs | C3: =E17+E32 -> 45
A4: Description | B4: Qty | C4: Days | D4: Rate | E4: Total
E5: =B5*C5*D5 -> 0
E6: =B6*C6*D6 -> 0
E7: =B7*C7*D7 -> 0
E8: =B8*C8*D8 -> 0
E9: =B9*C9*D9 -> 0
E10: =B10*C10*D10 -> 0
E11: =B11*C11*D11 -> 0
E12: =B12*C12*D12 -> 0
E13: =B13*C13*D13 -> 0
E14: =B14*C14*D14 -> 0
E15: =B15*C15*D15 -> 0
E16: =B16*C16*D16 -> 0
A17: Sum | E17: =SUM(E5:E16) -> 0
A18: OHSMS Equipment
A19: Description | B19: Qty | C19: Days | D19: Rate | E19: Total
E20: =B20*C20*D20 -> 0
A21: Escaleras | C21: 0 | D21: 5 | E21: =B21*C21*D21 -> 0
A22: Taladros | B22: 1 | C22: 3 | D22: 5 | E22: =B22*C22*D22 -> 15
A23: Band Saw | B23: 1 | C23: 3 | D23: 5 | E23: =B23*C23*D23 -> 15
A24: Llaves de ajuste | B24: 1 | C24: 3 | D24: 5 | E24: =B24*C24*D24 -> 15
E25: =B25*C25*D25 -> 0
E26: =B26*C26*D26 -> 0
E27: =B27*C27*D27 -> 0
E28: =B28*C28*D28 -> 0
E29: =B29*C29*D29 -> 0
E30: =B30*C30*D30 -> 0
E31: =B31*C31*D31 -> 0
A32: Sum | E32: =SUM(E20:E31) -> 45

Sheet General Conditions
A1: General Conditions
A3: Total GC Costs | C3: =E16+E29 -> 172.5
A4: Description | B4: Qty | C4: Unit | D4: Cost | E4: Total
A5: Agua | B5: 8 | C5: gal | D5: 2.5 | E5: =B5*D5 -> 20
A6: hielo | B6: 5 | C6: ea | D6: 2.5 | E6: =B6*D6 -> 12.5
A7: Telefono | B7: 1 | C7: ea | D7: 60 | E7: =B7*D7 -> 60
C8: ea | D8: 0 | E8: =B8*D8 -> 0
A9: Rotulos | B9: 1 | C9: ea | D9: 25 | E9: =B9*D9 -> 25
A10: Material Limpieza | C10: ea | D10: 20 | E10: =B10*D10 -> 0
A11: Cintas Perimetro | B11: 1 | C11: ea | D11: 25 | E11: =B11*D11 -> 25
A12: EPP | B12: 1 | C12: lot | D12: 30 | E12: =B12*D12 -> 30
E13: =B13*D13 -> 0
E14: =B14*D14 -> 0
E15: =B15*D15 -> 0
A16: Sum | E16: =SUM(E5:E15) -> 172.5
A17: Description | B17: Qty | C17: Unit | D17: Cost | E17: Total
E18: =B18*D18 -> 0
C19: ea | E19: =B19*D19 -> 0
E20: =B20*D20 -> 0
E21: =B21*D21 -> 0
E22: =B22*D22 -> 0
E23: =B23*D23 -> 0
E24: =B24*D24 -> 0
E25: =B25*D25 -> 0
E26: =B26*D26 -> 0
E27: =B27*D27 -> 0
E28: =B28*D28 -> 0
A29: Sum | E29: =SUM(E18:E28) -> 0

Sheet Sub-Contractors
A1: Sub-Contractors
A2: Civil
A3: SC | B3: Quoted Cost | C3: Assumed Cost
A15: Sum | B15: =SUM(B4:B14) -> 0 | C15: =SUM(C4:C14) -> 0
A16: Mechanical
A17: SC | B17: Quoted Cost | C17: Assumed Cost
A29: Sum | B29: =SUM(B18:B28) -> 0 | C29: =SUM(C18:C28) -> 0
A30: Electrical
A31: SC | B31: Quoted Cost | C31: Assumed Cost
A43: Sum | B43: =SUM(B32:B42) -> 0 | C43: =SUM(C32:C42) -> 0

Sheet Roundtrip
A1: Roundtrip
A3: Total Roundtrip Costs | C3: =E16 -> 0
A4: Pueblo | B4: Millas por viaje | C4: Costo por milla | D4: Dias | E4: Total
A5: Fajardo | B5: 25 | C5: 0.85 | D5: 0 | E5: =(B5*2)*C5*D5 -> 0
A6: Gurabo | B6: 12 | C6: 0.85 | D6: 0 | E6: =(B6*2)*C6*D6 -> 0
A7: Cidra | B7: 60 | C7: 0.85 | E7: =(B7*2)*C7*D7 -> 0
A16: Sum | E16: =SUM(E5:E15) -> 0
